Workbook
Name admin: #REF!
Name Bas_clas: #REF!
Name Bas_Prov: #REF!
Name Base_1: #REF!
Name BASE_2: #REF!
Name BASE_ART: #REF!
Name Base_Gto: #REF!
Name Base_nom: #REF!
Name Base_Prod: #REF!
Name base_prv: #REF!
Name Base_rep: #REF!
Name Base_Venta: #REF!
Name Base1: #REF!
Name Clav_Prod: #REF!
Name Com_mestrab: #REF!
Name Com_ProvMens: #REF!
Name Comp_17: #REF!
Name comp_abr17: #REF!
Name Comp_Ene17: #REF!
Name Comp_EneAbr: #REF!
Name comp_feb17: #REF!
Name comp_Jul17: #REF!
Name Comp_Jun17: #REF!
Name comp_mar17: #REF!
Name consumo: #REF!
Name consumopt: #REF!
Name COSO: #REF!
Name Cto_Men17: #REF!
Name Dat_BasicPtos: #REF!
Name detalle: #REF!
Name Exit3Switch: #REF!
Name ExitDate: #REF!
Name ExitScenario: #REF!
Name ExitSwitch: #REF!
Name FDGDGFDHGFDHDH: #REF!
Name Gto_Mes: #REF!
Name homedepot: #REF!
Name Imp_Econ: #REF!
Name Inc_Vta: #REF!
Name InterestRate: #REF!
Name Inv_FinMay: #REF!
Name Inv_FinMens: #REF!
Name InV_Trab: #REF!
Name JHBFSDFJDSKFJKDSBFS: #REF!
Name Lista_productos: #REF!
Name NADFA: #REF!
Name Octubre20: #REF!
Name Ppto_Acum: #REF!
Name PROD_MAY: #REF!
Name promexjun17: #REF!
Name proveedores: #REF!
Name Scenario: #REF!
Name sdnbsfsk: #REF!
Name Sponsor1EquityShare: #REF!
Name Sponsor2EquityShare: #REF!
Name SuccesPremiumSwitch: #REF!
Name TC: #REF!
Name TCENE: #REF!
Name Telemarketing: #REF!
Name toña: #REF!

Sheet EERR
C2: Project Shine - Combined Group
C3: P&L
C8: MXN | D8: 2022 | E8: 2023 | F8: 2024 | G8: =+F8+1 -> 2025
A9: x | B9: x | C9: Profit & Loss
B11: x | C11: Revenues
C12: Sales | D12: {=(_xlfn.XLOOKUP($C12,'[1]Commercialization Co.'!$C$11:$C$158,'[1]Commercialization Co.'!D$11:D$158,_xleta.N/A,0))+(_xlfn.XLOOKUP(EERR!$C12,'[1]Manufacturing Co.'!$C$11:$C$140,'[1]Manufacturing Co.'!D$11:D$140,_xleta.N/A,0))+(_xlfn.XLOOKUP(EERR!$C12,'[1]Admin Co.'!$C$11:$C$138,'[1]Admin Co.'!D$11:D$138,_xleta.N/A,0))} -> 2.1198984e+09 | E12: {=(_xlfn.XLOOKUP($C12,'[1]Commercialization Co.'!$C$11:$C$158,'[1]Commercialization Co.'!E$11:E$158,_xleta.N/A,0))+(_xlfn.XLOOKUP(EERR!$C12,'[1]Manufacturing Co.'!$C$11:$C$140,'[1]Manufacturing Co.'!E$11:E$140,_xleta.N/A,0))+(_xlfn.XLOOKUP(EERR!$C12,'[1]Admin Co.'!$C$11:$C$138,'[1]Admin Co.'!E$11:E$138,_xleta.N/A,0))} -> 2.6072219e+09 | F12: {=(_xlfn.XLOOKUP($C12,'[1]Commercialization Co.'!$C$11:$C$158,'[1]Commercialization Co.'!F$11:F$158,_xleta.N/A,0))+(_xlfn.XLOOKUP(EERR!$C12,'[1]Manufacturing Co.'!$C$11:$C$140,'[1]Manufacturing Co.'!F$11:F$140,_xleta.N/A,0))+(_xlfn.XLOOKUP(EERR!$C12,'[1]Admin Co.'!$C$11:$C$138,'[1]Admin Co.'!F$11:F$138,_xleta.N/A,0))} -> 2.6778316e+09 | G12: {=(_xlfn.XLOOKUP($C12,'[1]Commercialization Co.'!$C$11:$C$158,'[1]Commercialization Co.'!G$11:G$158,_xleta.N/A,0))+(_xlfn.XLOOKUP(EERR!$C12,'[1]Manufacturing Co.'!$C$11:$C$140,'[1]Manufacturing Co.'!G$11:G$140,_xleta.N/A,0))+(_xlfn.XLOOKUP(EERR!$C12,'[1]Admin Co.'!$C$11:$C$138,'[1]Admin Co.'!G$11:G$138,_xleta.N/A,0))} -> 2.4030047e+09
C13: (-) Returns and Discounts | D13: {=(_xlfn.XLOOKUP($C13,'[1]Commercialization Co.'!$C$11:$C$158,'[1]Commercialization Co.'!D$11:D$158,_xleta.N/A,0))+(_xlfn.XLOOKUP(EERR!$C13,'[1]Manufacturing Co.'!$C$11:$C$140,'[1]Manufacturing Co.'!D$11:D$140,_xleta.N/A,0))+(_xlfn.XLOOKUP(EERR!$C13,'[1]Admin Co.'!$C$11:$C$138,'[1]Admin Co.'!D$11:D$138,_xleta.N/A,0))} -> -1.4290286e+08 | E13: {=(_xlfn.XLOOKUP($C13,'[1]Commercialization Co.'!$C$11:$C$158,'[1]Commercialization Co.'!E$11:E$158,_xleta.N/A,0))+(_xlfn.XLOOKUP(EERR!$C13,'[1]Manufacturing Co.'!$C$11:$C$140,'[1]Manufacturing Co.'!E$11:E$140,_xleta.N/A,0))+(_xlfn.XLOOKUP(EERR!$C13,'[1]Admin Co.'!$C$11:$C$138,'[1]Admin Co.'!E$11:E$138,_xleta.N/A,0))} -> -1.9937495e+08 | F13: {=(_xlfn.XLOOKUP($C13,'[1]Commercialization Co.'!$C$11:$C$158,'[1]Commercialization Co.'!F$11:F$158,_xleta.N/A,0))+(_xlfn.XLOOKUP(EERR!$C13,'[1]Manufacturing Co.'!$C$11:$C$140,'[1]Manufacturing Co.'!F$11:F$140,_xleta.N/A,0))+(_xlfn.XLOOKUP(EERR!$C13,'[1]Admin Co.'!$C$11:$C$138,'[1]Admin Co.'!F$11:F$138,_xleta.N/A,0))} -> -3.0421937e+08 | G13: {=(_xlfn.XLOOKUP($C13,'[1]Commercialization Co.'!$C$11:$C$158,'[1]Commercialization Co.'!G$11:G$158,_xleta.N/A,0))+(_xlfn.XLOOKUP(EERR!$C13,'[1]Manufacturing Co.'!$C$11:$C$140,'[1]Manufacturing Co.'!G$11:G$140,_xleta.N/A,0))+(_xlfn.XLOOKUP(EERR!$C13,'[1]Admin Co.'!$C$11:$C$138,'[1]Admin Co.'!G$11:G$138,_xleta.N/A,0))} -> -2.6891315e+08
C14: (-) PISA Sales | D14: =[1]InterCompany!D14 -> -39600000 | E14: =[1]InterCompany!E14 -> -74640000 | F14: =[1]InterCompany!F14 -> -77718000 | G14: =[1]InterCompany!G14 -> -102367200
C15: (-) PIMA Sales to PI | D15: =[1]InterCompany!D15 -> -1.6167571e+08 | E15: =[1]InterCompany!E15 -> -2.1937091e+08 | F15: =[1]InterCompany!F15 -> -2.4518799e+08 | G15: =[1]InterCompany!G15 -> -2.2520747e+08
C16: Total Revenue | D16: =SUM(D12:D15) -> 1.7757198e+09 | E16: =SUM(E12:E15) -> 2.113836e+09 | F16: =SUM(F12:F15) -> 2.0507063e+09 | G16: =SUM(G12:G15) -> 1.8065169e+09
C17: growth % | D17: =+IFERROR((D16/C16)-1,"NA") -> NA | E17: =+IFERROR((E16/D16)-1,"NA") -> 0.1904108 | F17: =+IFERROR((F16/E16)-1,"NA") -> -0.029865018 | G17: =+IFERROR((G16/F16)-1,"NA") -> -0.11907576
B19: x | C19: COGS
C20: (-) Cost of Goods Sold | D20: =_xlfn.XLOOKUP($C20,'[1]Commercialization Co.'!$C$9:$C$171,'[1]Commercialization Co.'!D$9:D$171,0,0)+(_xlfn.XLOOKUP($C20,'[1]Manufacturing Co.'!$C$9:$C$147,'[1]Manufacturing Co.'!D$9:D$147,0,0))+(_xlfn.XLOOKUP($C20,'[1]Admin Co.'!$C$9:$C$148,'[1]Admin Co.'!D$9:D$148,0,0)) -> -1.1329568e+09 | E20: =_xlfn.XLOOKUP($C20,'[1]Commercialization Co.'!$C$9:$C$171,'[1]Commercialization Co.'!E$9:E$171,0,0)+(_xlfn.XLOOKUP($C20,'[1]Manufacturing Co.'!$C$9:$C$147,'[1]Manufacturing Co.'!E$9:E$147,0,0))+(_xlfn.XLOOKUP($C20,'[1]Admin Co.'!$C$9:$C$148,'[1]Admin Co.'!E$9:E$148,0,0)) -> -1.2251644e+09 | F20: =_xlfn.XLOOKUP($C20,'[1]Commercialization Co.'!$C$9:$C$171,'[1]Commercialization Co.'!F$9:F$171,0,0)+(_xlfn.XLOOKUP($C20,'[1]Manufacturing Co.'!$C$9:$C$147,'[1]Manufacturing Co.'!F$9:F$147,0,0))+(_xlfn.XLOOKUP($C20,'[1]Admin Co.'!$C$9:$C$148,'[1]Admin Co.'!F$9:F$148,0,0)) -> -1.2458014e+09 | G20: =_xlfn.XLOOKUP($C20,'[1]Commercialization Co.'!$C$9:$C$171,'[1]Commercialization Co.'!G$9:G$171,0,0)+(_xlfn.XLOOKUP($C20,'[1]Manufacturing Co.'!$C$9:$C$147,'[1]Manufacturing Co.'!G$9:G$147,0,0))+(_xlfn.XLOOKUP($C20,'[1]Admin Co.'!$C$9:$C$148,'[1]Admin Co.'!G$9:G$148,0,0)) -> -1.1015311e+09
C21: (-) Financial Gain (loss) | D21: =_xlfn.XLOOKUP($C21,'[1]Commercialization Co.'!$C$9:$C$171,'[1]Commercialization Co.'!D$9:D$171,0,0)+(_xlfn.XLOOKUP($C21,'[1]Manufacturing Co.'!$C$9:$C$147,'[1]Manufacturing Co.'!D$9:D$147,0,0))+(_xlfn.XLOOKUP($C21,'[1]Admin Co.'!$C$9:$C$148,'[1]Admin Co.'!D$9:D$148,0,0)) -> 0 | E21: =_xlfn.XLOOKUP($C21,'[1]Commercialization Co.'!$C$9:$C$171,'[1]Commercialization Co.'!E$9:E$171,0,0)+(_xlfn.XLOOKUP($C21,'[1]Manufacturing Co.'!$C$9:$C$147,'[1]Manufacturing Co.'!E$9:E$147,0,0))+(_xlfn.XLOOKUP($C21,'[1]Admin Co.'!$C$9:$C$148,'[1]Admin Co.'!E$9:E$148,0,0)) -> 0 | F21: =_xlfn.XLOOKUP($C21,'[1]Commercialization Co.'!$C$9:$C$171,'[1]Commercialization Co.'!F$9:F$171,0,0)+(_xlfn.XLOOKUP($C21,'[1]Manufacturing Co.'!$C$9:$C$147,'[1]Manufacturing Co.'!F$9:F$147,0,0))+(_xlfn.XLOOKUP($C21,'[1]Admin Co.'!$C$9:$C$148,'[1]Admin Co.'!F$9:F$148,0,0)) -> 0 | G21: =_xlfn.XLOOKUP($C21,'[1]Commercialization Co.'!$C$9:$C$171,'[1]Commercialization Co.'!G$9:G$171,0,0)+(_xlfn.XLOOKUP($C21,'[1]Manufacturing Co.'!$C$9:$C$147,'[1]Manufacturing Co.'!G$9:G$147,0,0))+(_xlfn.XLOOKUP($C21,'[1]Admin Co.'!$C$9:$C$148,'[1]Admin Co.'!G$9:G$148,0,0)) -> 0
C22: (-) Manufacturing COGS | D22: =_xlfn.XLOOKUP($C22,'[1]Commercialization Co.'!$C$9:$C$171,'[1]Commercialization Co.'!D$9:D$171,0,0)+(_xlfn.XLOOKUP($C22,'[1]Manufacturing Co.'!$C$9:$C$147,'[1]Manufacturing Co.'!D$9:D$147,0,0))+(_xlfn.XLOOKUP($C22,'[1]Admin Co.'!$C$9:$C$148,'[1]Admin Co.'!D$9:D$148,0,0)) -> -78765652 | E22: =_xlfn.XLOOKUP($C22,'[1]Commercialization Co.'!$C$9:$C$171,'[1]Commercialization Co.'!E$9:E$171,0,0)+(_xlfn.XLOOKUP($C22,'[1]Manufacturing Co.'!$C$9:$C$147,'[1]Manufacturing Co.'!E$9:E$147,0,0))+(_xlfn.XLOOKUP($C22,'[1]Admin Co.'!$C$9:$C$148,'[1]Admin Co.'!E$9:E$148,0,0)) -> -1.4915447e+08 | F22: =_xlfn.XLOOKUP($C22,'[1]Commercialization Co.'!$C$9:$C$171,'[1]Commercialization Co.'!F$9:F$171,0,0)+(_xlfn.XLOOKUP($C22,'[1]Manufacturing Co.'!$C$9:$C$147,'[1]Manufacturing Co.'!F$9:F$147,0,0))+(_xlfn.XLOOKUP($C22,'[1]Admin Co.'!$C$9:$C$148,'[1]Admin Co.'!F$9:F$148,0,0)) -> -1.6972431e+08 | G22: =_xlfn.XLOOKUP($C22,'[1]Commercialization Co.'!$C$9:$C$171,'[1]Commercialization Co.'!G$9:G$171,0,0)+(_xlfn.XLOOKUP($C22,'[1]Manufacturing Co.'!$C$9:$C$147,'[1]Manufacturing Co.'!G$9:G$147,0,0))+(_xlfn.XLOOKUP($C22,'[1]Admin Co.'!$C$9:$C$148,'[1]Admin Co.'!G$9:G$148,0,0)) -> -1.3702128e+08
C23: (-) Labour COGS | D23: =_xlfn.XLOOKUP($C23,'[1]Commercialization Co.'!$C$9:$C$171,'[1]Commercialization Co.'!D$9:D$171,0,0)+(_xlfn.XLOOKUP($C23,'[1]Manufacturing Co.'!$C$9:$C$147,'[1]Manufacturing Co.'!D$9:D$147,0,0))+(_xlfn.XLOOKUP($C23,'[1]Admin Co.'!$C$9:$C$148,'[1]Admin Co.'!D$9:D$148,0,0)) -> -36442614 | E23: =_xlfn.XLOOKUP($C23,'[1]Commercialization Co.'!$C$9:$C$171,'[1]Commercialization Co.'!E$9:E$171,0,0)+(_xlfn.XLOOKUP($C23,'[1]Manufacturing Co.'!$C$9:$C$147,'[1]Manufacturing Co.'!E$9:E$147,0,0))+(_xlfn.XLOOKUP($C23,'[1]Admin Co.'!$C$9:$C$148,'[1]Admin Co.'!E$9:E$148,0,0)) -> -52271544 | F23: =_xlfn.XLOOKUP($C23,'[1]Commercialization Co.'!$C$9:$C$171,'[1]Commercialization Co.'!F$9:F$171,0,0)+(_xlfn.XLOOKUP($C23,'[1]Manufacturing Co.'!$C$9:$C$147,'[1]Manufacturing Co.'!F$9:F$147,0,0))+(_xlfn.XLOOKUP($C23,'[1]Admin Co.'!$C$9:$C$148,'[1]Admin Co.'!F$9:F$148,0,0)) -> -56105758 | G23: =_xlfn.XLOOKUP($C23,'[1]Commercialization Co.'!$C$9:$C$171,'[1]Commercialization Co.'!G$9:G$171,0,0)+(_xlfn.XLOOKUP($C23,'[1]Manufacturing Co.'!$C$9:$C$147,'[1]Manufacturing Co.'!G$9:G$147,0,0))+(_xlfn.XLOOKUP($C23,'[1]Admin Co.'!$C$9:$C$148,'[1]Admin Co.'!G$9:G$148,0,0)) -> -56931664
C24: (-) Depreciation COGS | D24: =_xlfn.XLOOKUP($C24,'[1]Commercialization Co.'!$C$9:$C$171,'[1]Commercialization Co.'!D$9:D$171,0,0)+(_xlfn.XLOOKUP($C24,'[1]Manufacturing Co.'!$C$9:$C$147,'[1]Manufacturing Co.'!D$9:D$147,0,0))+(_xlfn.XLOOKUP($C24,'[1]Admin Co.'!$C$9:$C$148,'[1]Admin Co.'!D$9:D$148,0,0)) -> -75809 | E24: =_xlfn.XLOOKUP($C24,'[1]Commercialization Co.'!$C$9:$C$171,'[1]Commercialization Co.'!E$9:E$171,0,0)+(_xlfn.XLOOKUP($C24,'[1]Manufacturing Co.'!$C$9:$C$147,'[1]Manufacturing Co.'!E$9:E$147,0,0))+(_xlfn.XLOOKUP($C24,'[1]Admin Co.'!$C$9:$C$148,'[1]Admin Co.'!E$9:E$148,0,0)) -> -107093.27 | F24: =_xlfn.XLOOKUP($C24,'[1]Commercialization Co.'!$C$9:$C$171,'[1]Commercialization Co.'!F$9:F$171,0,0)+(_xlfn.XLOOKUP($C24,'[1]Manufacturing Co.'!$C$9:$C$147,'[1]Manufacturing Co.'!F$9:F$147,0,0))+(_xlfn.XLOOKUP($C24,'[1]Admin Co.'!$C$9:$C$148,'[1]Admin Co.'!F$9:F$148,0,0)) -> -107093.28 | G24: =_xlfn.XLOOKUP($C24,'[1]Commercialization Co.'!$C$9:$C$171,'[1]Commercialization Co.'!G$9:G$171,0,0)+(_xlfn.XLOOKUP($C24,'[1]Manufacturing Co.'!$C$9:$C$147,'[1]Manufacturing Co.'!G$9:G$147,0,0))+(_xlfn.XLOOKUP($C24,'[1]Admin Co.'!$C$9:$C$148,'[1]Admin Co.'!G$9:G$148,0,0)) -> -131232.06
C25: (-) Amortization COGS | D25: =_xlfn.XLOOKUP($C25,'[1]Commercialization Co.'!$C$9:$C$171,'[1]Commercialization Co.'!D$9:D$171,0,0)+(_xlfn.XLOOKUP($C25,'[1]Manufacturing Co.'!$C$9:$C$147,'[1]Manufacturing Co.'!D$9:D$147,0,0))+(_xlfn.XLOOKUP($C25,'[1]Admin Co.'!$C$9:$C$148,'[1]Admin Co.'!D$9:D$148,0,0)) -> -72407.49 | E25: =_xlfn.XLOOKUP($C25,'[1]Commercialization Co.'!$C$9:$C$171,'[1]Commercialization Co.'!E$9:E$171,0,0)+(_xlfn.XLOOKUP($C25,'[1]Manufacturing Co.'!$C$9:$C$147,'[1]Manufacturing Co.'!E$9:E$147,0,0))+(_xlfn.XLOOKUP($C25,'[1]Admin Co.'!$C$9:$C$148,'[1]Admin Co.'!E$9:E$148,0,0)) -> -788723.5 | F25: =_xlfn.XLOOKUP($C25,'[1]Commercialization Co.'!$C$9:$C$171,'[1]Commercialization Co.'!F$9:F$171,0,0)+(_xlfn.XLOOKUP($C25,'[1]Manufacturing Co.'!$C$9:$C$147,'[1]Manufacturing Co.'!F$9:F$147,0,0))+(_xlfn.XLOOKUP($C25,'[1]Admin Co.'!$C$9:$C$148,'[1]Admin Co.'!F$9:F$148,0,0)) -> -1657542.1 | G25: =_xlfn.XLOOKUP($C25,'[1]Commercialization Co.'!$C$9:$C$171,'[1]Commercialization Co.'!G$9:G$171,0,0)+(_xlfn.XLOOKUP($C25,'[1]Manufacturing Co.'!$C$9:$C$147,'[1]Manufacturing Co.'!G$9:G$147,0,0))+(_xlfn.XLOOKUP($C25,'[1]Admin Co.'!$C$9:$C$148,'[1]Admin Co.'!G$9:G$148,0,0)) -> -1964129.6
C26: (+) PI COGS caused by PIMA | D26: =[1]InterCompany!D19 -> 1.6167571e+08 | E26: =[1]InterCompany!E19 -> 2.1937091e+08 | F26: =[1]InterCompany!F19 -> 2.4518799e+08 | G26: =[1]InterCompany!G19 -> 2.2520747e+08
C27: (+) Rent expense from PIMA to PI | D27: =[1]InterCompany!D20 -> 22359567 | E27: =[1]InterCompany!E20 -> 24655711 | F27: =[1]InterCompany!F20 -> 25814624 | G27: =[1]InterCompany!G20 -> 23314412
C28: Total COGS | D28: =SUM(D20:D27) -> -1.064278e+09 | E28: =SUM(E20:E27) -> -1.1834596e+09 | F28: =SUM(F20:F27) -> -1.2023935e+09 | G28: =SUM(G20:G27) -> -1.0490575e+09
C30: Gross Profit | D30: =D28+D16 -> 7.1144177e+08 | E30: =E28+E16 -> 9.3037643e+08 | F30: =F28+F16 -> 8.4831274e+08 | G30: =G28+G16 -> 7.5745933e+08
C31: Gross margin % | D31: =D30/D$16 -> 0.4006498 | E31: =E30/E$16 -> 0.44013652 | F31: =F30/F$16 -> 0.41366857 | G31: =G30/G$16 -> 0.4192927
B33: x | C33: SG&A
C34: (-) Manufacturing Expenses | D34: =_xlfn.XLOOKUP($C34,'[1]Commercialization Co.'!$C$9:$C$171,'[1]Commercialization Co.'!D$9:D$171,0,0)+(_xlfn.XLOOKUP($C34,'[1]Manufacturing Co.'!$C$9:$C$147,'[1]Manufacturing Co.'!D$9:D$147,0,0))+(_xlfn.XLOOKUP($C34,'[1]Admin Co.'!$C$9:$C$148,'[1]Admin Co.'!D$9:D$148,0,0)) -> 13784638 | E34: =_xlfn.XLOOKUP($C34,'[1]Commercialization Co.'!$C$9:$C$171,'[1]Commercialization Co.'!E$9:E$171,0,0)+(_xlfn.XLOOKUP($C34,'[1]Manufacturing Co.'!$C$9:$C$147,'[1]Manufacturing Co.'!E$9:E$147,0,0))+(_xlfn.XLOOKUP($C34,'[1]Admin Co.'!$C$9:$C$148,'[1]Admin Co.'!E$9:E$148,0,0)) -> 27423615 | F34: =_xlfn.XLOOKUP($C34,'[1]Commercialization Co.'!$C$9:$C$171,'[1]Commercialization Co.'!F$9:F$171,0,0)+(_xlfn.XLOOKUP($C34,'[1]Manufacturing Co.'!$C$9:$C$147,'[1]Manufacturing Co.'!F$9:F$147,0,0))+(_xlfn.XLOOKUP($C34,'[1]Admin Co.'!$C$9:$C$148,'[1]Admin Co.'!F$9:F$148,0,0)) -> 32887234 | G34: =_xlfn.XLOOKUP($C34,'[1]Commercialization Co.'!$C$9:$C$171,'[1]Commercialization Co.'!G$9:G$171,0,0)+(_xlfn.XLOOKUP($C34,'[1]Manufacturing Co.'!$C$9:$C$147,'[1]Manufacturing Co.'!G$9:G$147,0,0))+(_xlfn.XLOOKUP($C34,'[1]Admin Co.'!$C$9:$C$148,'[1]Admin Co.'!G$9:G$148,0,0)) -> -53025905
C35: (-) Selling Expenses | D35: =_xlfn.XLOOKUP($C35,'[1]Commercialization Co.'!$C$9:$C$171,'[1]Commercialization Co.'!D$9:D$171,0,0)+(_xlfn.XLOOKUP($C35,'[1]Manufacturing Co.'!$C$9:$C$147,'[1]Manufacturing Co.'!D$9:D$147,0,0))+(_xlfn.XLOOKUP($C35,'[1]Admin Co.'!$C$9:$C$148,'[1]Admin Co.'!D$9:D$148,0,0)) -> -51807171 | E35: =_xlfn.XLOOKUP($C35,'[1]Commercialization Co.'!$C$9:$C$171,'[1]Commercialization Co.'!E$9:E$171,0,0)+(_xlfn.XLOOKUP($C35,'[1]Manufacturing Co.'!$C$9:$C$147,'[1]Manufacturing Co.'!E$9:E$147,0,0))+(_xlfn.XLOOKUP($C35,'[1]Admin Co.'!$C$9:$C$148,'[1]Admin Co.'!E$9:E$148,0,0)) -> -61739773 | F35: =_xlfn.XLOOKUP($C35,'[1]Commercialization Co.'!$C$9:$C$171,'[1]Commercialization Co.'!F$9:F$171,0,0)+(_xlfn.XLOOKUP($C35,'[1]Manufacturing Co.'!$C$9:$C$147,'[1]Manufacturing Co.'!F$9:F$147,0,0))+(_xlfn.XLOOKUP($C35,'[1]Admin Co.'!$C$9:$C$148,'[1]Admin Co.'!F$9:F$148,0,0)) -> -1.0034556e+08 | G35: =_xlfn.XLOOKUP($C35,'[1]Commercialization Co.'!$C$9:$C$171,'[1]Commercialization Co.'!G$9:G$171,0,0)+(_xlfn.XLOOKUP($C35,'[1]Manufacturing Co.'!$C$9:$C$147,'[1]Manufacturing Co.'!G$9:G$147,0,0))+(_xlfn.XLOOKUP($C35,'[1]Admin Co.'!$C$9:$C$148,'[1]Admin Co.'!G$9:G$148,0,0)) -> -78927213
C36: (-) Freight Expense | D36: =_xlfn.XLOOKUP($C36,'[1]Commercialization Co.'!$C$9:$C$171,'[1]Commercialization Co.'!D$9:D$171,0,0)+(_xlfn.XLOOKUP($C36,'[1]Manufacturing Co.'!$C$9:$C$147,'[1]Manufacturing Co.'!D$9:D$147,0,0))+(_xlfn.XLOOKUP($C36,'[1]Admin Co.'!$C$9:$C$148,'[1]Admin Co.'!D$9:D$148,0,0)) -> -1.7265113e+08 | E36: =_xlfn.XLOOKUP($C36,'[1]Commercialization Co.'!$C$9:$C$171,'[1]Commercialization Co.'!E$9:E$171,0,0)+(_xlfn.XLOOKUP($C36,'[1]Manufacturing Co.'!$C$9:$C$147,'[1]Manufacturing Co.'!E$9:E$147,0,0))+(_xlfn.XLOOKUP($C36,'[1]Admin Co.'!$C$9:$C$148,'[1]Admin Co.'!E$9:E$148,0,0)) -> -1.7009586e+08 | F36: =_xlfn.XLOOKUP($C36,'[1]Commercialization Co.'!$C$9:$C$171,'[1]Commercialization Co.'!F$9:F$171,0,0)+(_xlfn.XLOOKUP($C36,'[1]Manufacturing Co.'!$C$9:$C$147,'[1]Manufacturing Co.'!F$9:F$147,0,0))+(_xlfn.XLOOKUP($C36,'[1]Admin Co.'!$C$9:$C$148,'[1]Admin Co.'!F$9:F$148,0,0)) -> -1.5656129e+08 | G36: =_xlfn.XLOOKUP($C36,'[1]Commercialization Co.'!$C$9:$C$171,'[1]Commercialization Co.'!G$9:G$171,0,0)+(_xlfn.XLOOKUP($C36,'[1]Manufacturing Co.'!$C$9:$C$147,'[1]Manufacturing Co.'!G$9:G$147,0,0))+(_xlfn.XLOOKUP($C36,'[1]Admin Co.'!$C$9:$C$148,'[1]Admin Co.'!G$9:G$148,0,0)) -> -1.4022657e+08
C37: (-) Administrative Expenses | D37: =_xlfn.XLOOKUP($C37,'[1]Commercialization Co.'!$C$9:$C$171,'[1]Commercialization Co.'!D$9:D$171,0,0)+(_xlfn.XLOOKUP($C37,'[1]Manufacturing Co.'!$C$9:$C$147,'[1]Manufacturing Co.'!D$9:D$147,0,0))+(_xlfn.XLOOKUP($C37,'[1]Admin Co.'!$C$9:$C$148,'[1]Admin Co.'!D$9:D$148,0,0)) -> -87991671 | E37: =_xlfn.XLOOKUP($C37,'[1]Commercialization Co.'!$C$9:$C$171,'[1]Commercialization Co.'!E$9:E$171,0,0)+(_xlfn.XLOOKUP($C37,'[1]Manufacturing Co.'!$C$9:$C$147,'[1]Manufacturing Co.'!E$9:E$147,0,0))+(_xlfn.XLOOKUP($C37,'[1]Admin Co.'!$C$9:$C$148,'[1]Admin Co.'!E$9:E$148,0,0)) -> -1.0516721e+08 | F37: =_xlfn.XLOOKUP($C37,'[1]Commercialization Co.'!$C$9:$C$171,'[1]Commercialization Co.'!F$9:F$171,0,0)+(_xlfn.XLOOKUP($C37,'[1]Manufacturing Co.'!$C$9:$C$147,'[1]Manufacturing Co.'!F$9:F$147,0,0))+(_xlfn.XLOOKUP($C37,'[1]Admin Co.'!$C$9:$C$148,'[1]Admin Co.'!F$9:F$148,0,0)) -> -1.2163395e+08 | G37: =_xlfn.XLOOKUP($C37,'[1]Commercialization Co.'!$C$9:$C$171,'[1]Commercialization Co.'!G$9:G$171,0,0)+(_xlfn.XLOOKUP($C37,'[1]Manufacturing Co.'!$C$9:$C$147,'[1]Manufacturing Co.'!G$9:G$147,0,0))+(_xlfn.XLOOKUP($C37,'[1]Admin Co.'!$C$9:$C$148,'[1]Admin Co.'!G$9:G$148,0,0)) -> -1.940618e+08
C38: (-) Management Expenses | D38: =_xlfn.XLOOKUP($C38,'[1]Commercialization Co.'!$C$9:$C$171,'[1]Commercialization Co.'!D$9:D$171,0,0)+(_xlfn.XLOOKUP($C38,'[1]Manufacturing Co.'!$C$9:$C$147,'[1]Manufacturing Co.'!D$9:D$147,0,0))+(_xlfn.XLOOKUP($C38,'[1]Admin Co.'!$C$9:$C$148,'[1]Admin Co.'!D$9:D$148,0,0)) -> -4100087.2 | E38: =_xlfn.XLOOKUP($C38,'[1]Commercialization Co.'!$C$9:$C$171,'[1]Commercialization Co.'!E$9:E$171,0,0)+(_xlfn.XLOOKUP($C38,'[1]Manufacturing Co.'!$C$9:$C$147,'[1]Manufacturing Co.'!E$9:E$147,0,0))+(_xlfn.XLOOKUP($C38,'[1]Admin Co.'!$C$9:$C$148,'[1]Admin Co.'!E$9:E$148,0,0)) -> -6267090.1 | F38: =_xlfn.XLOOKUP($C38,'[1]Commercialization Co.'!$C$9:$C$171,'[1]Commercialization Co.'!F$9:F$171,0,0)+(_xlfn.XLOOKUP($C38,'[1]Manufacturing Co.'!$C$9:$C$147,'[1]Manufacturing Co.'!F$9:F$147,0,0))+(_xlfn.XLOOKUP($C38,'[1]Admin Co.'!$C$9:$C$148,'[1]Admin Co.'!F$9:F$148,0,0)) -> -7941121.6 | G38: =_xlfn.XLOOKUP($C38,'[1]Commercialization Co.'!$C$9:$C$171,'[1]Commercialization Co.'!G$9:G$171,0,0)+(_xlfn.XLOOKUP($C38,'[1]Manufacturing Co.'!$C$9:$C$147,'[1]Manufacturing Co.'!G$9:G$147,0,0))+(_xlfn.XLOOKUP($C38,'[1]Admin Co.'!$C$9:$C$148,'[1]Admin Co.'!G$9:G$148,0,0)) -> -7198812.3
C39: (-) Depreciation Expenses | D39: =_xlfn.XLOOKUP($C39,'[1]Commercialization Co.'!$C$9:$C$171,'[1]Commercialization Co.'!D$9:D$171,0,0)+(_xlfn.XLOOKUP($C39,'[1]Manufacturing Co.'!$C$9:$C$147,'[1]Manufacturing Co.'!D$9:D$147,0,0))+(_xlfn.XLOOKUP($C39,'[1]Admin Co.'!$C$9:$C$148,'[1]Admin Co.'!D$9:D$148,0,0)) -> -37543575 | E39: =_xlfn.XLOOKUP($C39,'[1]Commercialization Co.'!$C$9:$C$171,'[1]Commercialization Co.'!E$9:E$171,0,0)+(_xlfn.XLOOKUP($C39,'[1]Manufacturing Co.'!$C$9:$C$147,'[1]Manufacturing Co.'!E$9:E$147,0,0))+(_xlfn.XLOOKUP($C39,'[1]Admin Co.'!$C$9:$C$148,'[1]Admin Co.'!E$9:E$148,0,0)) -> -54586270 | F39: =_xlfn.XLOOKUP($C39,'[1]Commercialization Co.'!$C$9:$C$171,'[1]Commercialization Co.'!F$9:F$171,0,0)+(_xlfn.XLOOKUP($C39,'[1]Manufacturing Co.'!$C$9:$C$147,'[1]Manufacturing Co.'!F$9:F$147,0,0))+(_xlfn.XLOOKUP($C39,'[1]Admin Co.'!$C$9:$C$148,'[1]Admin Co.'!F$9:F$148,0,0)) -> -37786676 | G39: =_xlfn.XLOOKUP($C39,'[1]Commercialization Co.'!$C$9:$C$171,'[1]Commercialization Co.'!G$9:G$171,0,0)+(_xlfn.XLOOKUP($C39,'[1]Manufacturing Co.'!$C$9:$C$147,'[1]Manufacturing Co.'!G$9:G$147,0,0))+(_xlfn.XLOOKUP($C39,'[1]Admin Co.'!$C$9:$C$148,'[1]Admin Co.'!G$9:G$148,0,0)) -> -35014244
C40: (-) Amortization Expenses | D40: =_xlfn.XLOOKUP($C40,'[1]Commercialization Co.'!$C$9:$C$171,'[1]Commercialization Co.'!D$9:D$171,0,0)+(_xlfn.XLOOKUP($C40,'[1]Manufacturing Co.'!$C$9:$C$147,'[1]Manufacturing Co.'!D$9:D$147,0,0))+(_xlfn.XLOOKUP($C40,'[1]Admin Co.'!$C$9:$C$148,'[1]Admin Co.'!D$9:D$148,0,0)) -> -2782893.1 | E40: =_xlfn.XLOOKUP($C40,'[1]Commercialization Co.'!$C$9:$C$171,'[1]Commercialization Co.'!E$9:E$171,0,0)+(_xlfn.XLOOKUP($C40,'[1]Manufacturing Co.'!$C$9:$C$147,'[1]Manufacturing Co.'!E$9:E$147,0,0))+(_xlfn.XLOOKUP($C40,'[1]Admin Co.'!$C$9:$C$148,'[1]Admin Co.'!E$9:E$148,0,0)) -> -2264368 | F40: =_xlfn.XLOOKUP($C40,'[1]Commercialization Co.'!$C$9:$C$171,'[1]Commercialization Co.'!F$9:F$171,0,0)+(_xlfn.XLOOKUP($C40,'[1]Manufacturing Co.'!$C$9:$C$147,'[1]Manufacturing Co.'!F$9:F$147,0,0))+(_xlfn.XLOOKUP($C40,'[1]Admin Co.'!$C$9:$C$148,'[1]Admin Co.'!F$9:F$148,0,0)) -> -2077480 | G40: =_xlfn.XLOOKUP($C40,'[1]Commercialization Co.'!$C$9:$C$171,'[1]Commercialization Co.'!G$9:G$171,0,0)+(_xlfn.XLOOKUP($C40,'[1]Manufacturing Co.'!$C$9:$C$147,'[1]Manufacturing Co.'!G$9:G$147,0,0))+(_xlfn.XLOOKUP($C40,'[1]Admin Co.'!$C$9:$C$148,'[1]Admin Co.'!G$9:G$148,0,0)) -> -2229597.7
C41: (-) Business Development & Monitoring Fees | D41: =_xlfn.XLOOKUP($C41,'[1]Commercialization Co.'!$C$9:$C$171,'[1]Commercialization Co.'!D$9:D$171,0,0)+(_xlfn.XLOOKUP($C41,'[1]Manufacturing Co.'!$C$9:$C$147,'[1]Manufacturing Co.'!D$9:D$147,0,0))+(_xlfn.XLOOKUP($C41,'[1]Admin Co.'!$C$9:$C$148,'[1]Admin Co.'!D$9:D$148,0,0)) -> 0 | E41: =_xlfn.XLOOKUP($C41,'[1]Commercialization Co.'!$C$9:$C$171,'[1]Commercialization Co.'!E$9:E$171,0,0)+(_xlfn.XLOOKUP($C41,'[1]Manufacturing Co.'!$C$9:$C$147,'[1]Manufacturing Co.'!E$9:E$147,0,0))+(_xlfn.XLOOKUP($C41,'[1]Admin Co.'!$C$9:$C$148,'[1]Admin Co.'!E$9:E$148,0,0)) -> 0 | F41: =_xlfn.XLOOKUP($C41,'[1]Commercialization Co.'!$C$9:$C$171,'[1]Commercialization Co.'!F$9:F$171,0,0)+(_xlfn.XLOOKUP($C41,'[1]Manufacturing Co.'!$C$9:$C$147,'[1]Manufacturing Co.'!F$9:F$147,0,0))+(_xlfn.XLOOKUP($C41,'[1]Admin Co.'!$C$9:$C$148,'[1]Admin Co.'!F$9:F$148,0,0)) -> 0 | G41: =_xlfn.XLOOKUP($C41,'[1]Commercialization Co.'!$C$9:$C$171,'[1]Commercialization Co.'!G$9:G$171,0,0)+(_xlfn.XLOOKUP($C41,'[1]Manufacturing Co.'!$C$9:$C$147,'[1]Manufacturing Co.'!G$9:G$147,0,0))+(_xlfn.XLOOKUP($C41,'[1]Admin Co.'!$C$9:$C$148,'[1]Admin Co.'!G$9:G$148,0,0)) -> 0
C42: (+) PI & PIMA SG&A caused by PISA | D42: =[1]InterCompany!D24 -> 39600000 | E42: =[1]InterCompany!E24 -> 74640000 | F42: =[1]InterCompany!F24 -> 77718000 | G42: =[1]InterCompany!G24 -> 102367200
C43: (+) Rent expense from PISA to PI | D43: =[1]InterCompany!D25 -> 376690.44 | E43: =[1]InterCompany!E25 -> 389881.38 | F43: =[1]InterCompany!F25 -> 404284.8 | G43: =[1]InterCompany!G25 -> 422970.39
C44: Total SG&A | D44: =SUM(D34:D43) -> -3.031152e+08 | E44: =SUM(E34:E43) -> -2.9766708e+08 | F44: =SUM(F34:F43) -> -3.1533656e+08 | G44: =SUM(G34:G43) -> -4.0789397e+08
C46: Operating Profit | D46: =D44+D30 -> 4.0832657e+08 | E46: =E44+E30 -> 6.3270936e+08 | F46: =F44+F30 -> 5.3297618e+08 | G46: =G44+G30 -> 3.4956536e+08
C47: Operating Profit margin % | D47: =D46/D$16 -> 0.22994989 | E47: =E46/E$16 -> 0.29931809 | F47: =F46/F$16 -> 0.25989884 | G47: =G46/G$16 -> 0.19350241
C49: (+) Financial products | D49: =_xlfn.XLOOKUP($C49,'[1]Commercialization Co.'!$C$9:$C$171,'[1]Commercialization Co.'!D$9:D$171,0,0)+(_xlfn.XLOOKUP($C49,'[1]Manufacturing Co.'!$C$9:$C$147,'[1]Manufacturing Co.'!D$9:D$147,0,0))+(_xlfn.XLOOKUP($C49,'[1]Admin Co.'!$C$9:$C$148,'[1]Admin Co.'!D$9:D$148,0,0)) -> 19950755 | E49: =_xlfn.XLOOKUP($C49,'[1]Commercialization Co.'!$C$9:$C$171,'[1]Commercialization Co.'!E$9:E$171,0,0)+(_xlfn.XLOOKUP($C49,'[1]Manufacturing Co.'!$C$9:$C$147,'[1]Manufacturing Co.'!E$9:E$147,0,0))+(_xlfn.XLOOKUP($C49,'[1]Admin Co.'!$C$9:$C$148,'[1]Admin Co.'!E$9:E$148,0,0)) -> 42373785 | F49: =_xlfn.XLOOKUP($C49,'[1]Commercialization Co.'!$C$9:$C$171,'[1]Commercialization Co.'!F$9:F$171,0,0)+(_xlfn.XLOOKUP($C49,'[1]Manufacturing Co.'!$C$9:$C$147,'[1]Manufacturing Co.'!F$9:F$147,0,0))+(_xlfn.XLOOKUP($C49,'[1]Admin Co.'!$C$9:$C$148,'[1]Admin Co.'!F$9:F$148,0,0)) -> 69743196 | G49: =_xlfn.XLOOKUP($C49,'[1]Commercialization Co.'!$C$9:$C$171,'[1]Commercialization Co.'!G$9:G$171,0,0)+(_xlfn.XLOOKUP($C49,'[1]Manufacturing Co.'!$C$9:$C$147,'[1]Manufacturing Co.'!G$9:G$147,0,0))+(_xlfn.XLOOKUP($C49,'[1]Admin Co.'!$C$9:$C$148,'[1]Admin Co.'!G$9:G$148,0,0)) -> 67523190
C50: (-) Financial expenses | D50: =_xlfn.XLOOKUP($C50,'[1]Commercialization Co.'!$C$9:$C$171,'[1]Commercialization Co.'!D$9:D$171,0,0)+(_xlfn.XLOOKUP($C50,'[1]Manufacturing Co.'!$C$9:$C$147,'[1]Manufacturing Co.'!D$9:D$147,0,0))+(_xlfn.XLOOKUP($C50,'[1]Admin Co.'!$C$9:$C$148,'[1]Admin Co.'!D$9:D$148,0,0)) -> -1241187.4 | E50: =_xlfn.XLOOKUP($C50,'[1]Commercialization Co.'!$C$9:$C$171,'[1]Commercialization Co.'!E$9:E$171,0,0)+(_xlfn.XLOOKUP($C50,'[1]Manufacturing Co.'!$C$9:$C$147,'[1]Manufacturing Co.'!E$9:E$147,0,0))+(_xlfn.XLOOKUP($C50,'[1]Admin Co.'!$C$9:$C$148,'[1]Admin Co.'!E$9:E$148,0,0)) -> -1235391.1 | F50: =_xlfn.XLOOKUP($C50,'[1]Commercialization Co.'!$C$9:$C$171,'[1]Commercialization Co.'!F$9:F$171,0,0)+(_xlfn.XLOOKUP($C50,'[1]Manufacturing Co.'!$C$9:$C$147,'[1]Manufacturing Co.'!F$9:F$147,0,0))+(_xlfn.XLOOKUP($C50,'[1]Admin Co.'!$C$9:$C$148,'[1]Admin Co.'!F$9:F$148,0,0)) -> -106947.13 | G50: =_xlfn.XLOOKUP($C50,'[1]Commercialization Co.'!$C$9:$C$171,'[1]Commercialization Co.'!G$9:G$171,0,0)+(_xlfn.XLOOKUP($C50,'[1]Manufacturing Co.'!$C$9:$C$147,'[1]Manufacturing Co.'!G$9:G$147,0,0))+(_xlfn.XLOOKUP($C50,'[1]Admin Co.'!$C$9:$C$148,'[1]Admin Co.'!G$9:G$148,0,0)) -> -91896.25
C51: (+/-) Exchange gain or loss | D51: =_xlfn.XLOOKUP($C51,'[1]Commercialization Co.'!$C$9:$C$171,'[1]Commercialization Co.'!D$9:D$171,0,0)+(_xlfn.XLOOKUP($C51,'[1]Manufacturing Co.'!$C$9:$C$147,'[1]Manufacturing Co.'!D$9:D$147,0,0))+(_xlfn.XLOOKUP($C51,'[1]Admin Co.'!$C$9:$C$148,'[1]Admin Co.'!D$9:D$148,0,0)) -> -369245.21 | E51: =_xlfn.XLOOKUP($C51,'[1]Commercialization Co.'!$C$9:$C$171,'[1]Commercialization Co.'!E$9:E$171,0,0)+(_xlfn.XLOOKUP($C51,'[1]Manufacturing Co.'!$C$9:$C$147,'[1]Manufacturing Co.'!E$9:E$147,0,0))+(_xlfn.XLOOKUP($C51,'[1]Admin Co.'!$C$9:$C$148,'[1]Admin Co.'!E$9:E$148,0,0)) -> -20938376 | F51: =_xlfn.XLOOKUP($C51,'[1]Commercialization Co.'!$C$9:$C$171,'[1]Commercialization Co.'!F$9:F$171,0,0)+(_xlfn.XLOOKUP($C51,'[1]Manufacturing Co.'!$C$9:$C$147,'[1]Manufacturing Co.'!F$9:F$147,0,0))+(_xlfn.XLOOKUP($C51,'[1]Admin Co.'!$C$9:$C$148,'[1]Admin Co.'!F$9:F$148,0,0)) -> 23804342 | G51: =_xlfn.XLOOKUP($C51,'[1]Commercialization Co.'!$C$9:$C$171,'[1]Commercialization Co.'!G$9:G$171,0,0)+(_xlfn.XLOOKUP($C51,'[1]Manufacturing Co.'!$C$9:$C$147,'[1]Manufacturing Co.'!G$9:G$147,0,0))+(_xlfn.XLOOKUP($C51,'[1]Admin Co.'!$C$9:$C$148,'[1]Admin Co.'!G$9:G$148,0,0)) -> -27395302
...
